<?xml version="1.0"?>
<robot name="snake_simulate" xmlns:xacro="http://www.ros.org/wiki/xacro">
    <xacro:macro name="snake_with_wheel_head" params="ID1:=1 ID2:=2 ID3:=2">
        <link name="dummy_link">
        </link>
        <link
            name="base_link">
            <inertial>
                <origin
                    xyz="0.046756 -3.0974E-05 -0.0042756"
                    rpy="0 0 0" />
                <mass
                    value="0.15651" />
                <inertia
                    ixx="6.9082E-05"
                    ixy="-8.9347E-08"
                    ixz="1.2498E-06"
                    iyy="0.00011157"
                    iyz="-1.7714E-09"
                    izz="9.5319E-05" />
            </inertial>
            <visual>
                <origin
                    xyz="0 0 0"
                    rpy="0 0 0" />
                <geometry>
                    <mesh
                        filename="package://snake_simulate/meshes/snake_with_wheel_base_link.STL" />
                </geometry>
                <material
                    name="">
                    <color
                        rgba="0.18431 0.73333 1 1" />
                </material>
            </visual>
            <collision>
                <origin
                    xyz="0 0 0"
                    rpy="0 0 0" />
                <geometry>
                    <mesh
                        filename="package://snake_simulate/meshes/snake_with_wheel_base_link.STL" />
                </geometry>
            </collision>
        </link>
        <joint name="dummy_joint" type="fixed">
            <parent link="dummy_link"/>
            <child link="base_link"/>
        </joint>
        <link
            name="Wheel_1">
            <inertial>
                <origin
                    xyz="-2.7756E-17 1.0582E-16 3.4694E-18"
                    rpy="0 0 0" />
                <mass
                    value="0.019471" />
                <inertia
                    ixx="4.07E-06"
                    ixy="-8.4946E-21"
                    ixz="9.3271E-24"
                    iyy="2.7774E-06"
                    iyz="1.1729E-11"
                    izz="4.07E-06" />
            </inertial>
            <visual>
                <origin
                    xyz="0 0 0"
                    rpy="0 0 0" />
                <geometry>
                    <mesh
                        filename="package://snake_simulate/meshes/snake_with_wheel_Wheel_1.STL" />
                </geometry>
                <material
                    name="">
                    <color
                        rgba="0.79608 0.82353 0.93725 1" />
                </material>
            </visual>
            <collision>
                <origin
                    xyz="0 0 0"
                    rpy="0 0 0" />
                <geometry>
                    <mesh
                        filename="package://snake_simulate/meshes/snake_with_wheel_Wheel_1.STL" />
                </geometry>
            </collision>
        </link>
        <joint
            name="Wheel_joint_1"
            type="continuous">
            <origin
                xyz="0.079 0 -0.03"
                rpy="0 0 0" />
            <parent
                link="base_link" />
            <child
                link="Wheel_1" />
            <axis
                xyz="0 1 0" />
            <limit
                lower="0"
                upper="0"
                effort="0"
                velocity="100" />
        </joint>
        <link
            name="Link_${ID1}">
            <inertial>
                <origin
                    xyz="-0.028507 -0.00015484 -3.6726E-05"
                    rpy="0 0 0" />
                <mass
                    value="0.3569" />
                <inertia
                    ixx="0.00010484"
                    ixy="-4.4703E-09"
                    ixz="1.6891E-07"
                    iyy="0.0001602"
                    iyz="2.9787E-10"
                    izz="0.00014581" />
            </inertial>
            <visual>
                <origin
                xyz="0 0 0"
                rpy="0 0 0" />
                <geometry>
                    <mesh
                        filename="package://snake_simulate/meshes/snake_with_wheel_Link_1.STL" />
                </geometry>
                <material
                    name="">
                    <color
                        rgba="0.77647 0.75686 0.73725 1" />
                </material>
            </visual>
            <collision>
                <origin
                    xyz="0 0 0"
                    rpy="0 0 0" />
                <geometry>
                    <mesh
                        filename="package://snake_simulate/meshes/snake_with_wheel_Link_1.STL" />
                </geometry>
            </collision>
        </link>
        <joint
            name="Joint_${ID1}"
            type="revolute">
            <origin
                xyz="0 0 0"
                rpy="0 0 0" />
            <parent
                link="base_link" />
            <child
                link="Link_${ID1}" />
            <axis
                xyz="0 0 -1" />
            <limit
                lower="-1.5"
                upper="1.5"
                effort="1000"
                velocity="50" />
        </joint>
        <link
            name="Link_${ID2}">
            <inertial>
                <origin
                    xyz="-0.029095 -0.0018076 -1.6348E-05"
                    rpy="0 0 0" />
                <mass
                    value="0.40492" />
                <inertia
                    ixx="0.00011158"
                    ixy="1.2455E-06"
                    ixz="1.6891E-07"
                    iyy="0.00016276"
                    iyz="2.9842E-10"
                    izz="0.00015263" />
            </inertial>
            <visual>
                <origin
                    xyz="0 0 0"
                    rpy="0 0 0" />
                <geometry>
                    <mesh
                        filename="package://snake_simulate/meshes/snake_with_wheel_Link_2.STL" />
                </geometry>
                <material
                    name="">
                    <color
                        rgba="0.77647 0.75686 0.73725 1" />
                </material>
            </visual>
            <collision>
                <origin
                    xyz="0 0 0"
                    rpy="0 0 0" />
                <geometry>
                    <mesh
                        filename="package://snake_simulate/meshes/snake_with_wheel_Link_2.STL" />
                </geometry>
            </collision>
        </link>
        <joint
            name="Joint_${ID2}"
            type="revolute">
            <origin
                xyz="-0.1059 -0.00015556 0"
                rpy="1.5708 0 0" />
            <parent
                link="Link_${ID1}" />
            <child
                link="Link_${ID2}" />
            <axis
                xyz="0 0 -1" />
            <limit
                lower="-1.5"
                upper="1.5"
                effort="1000"
                velocity="50" />
        </joint>
        <link
            name="Wheel_${ID3}">
            <inertial>
                <origin
                    xyz="-5.5511E-17 3.1225E-17 1.9082E-17"
                    rpy="0 0 0" />
                <mass
                    value="0.019471" />
                <inertia
                    ixx="4.07E-06"
                    ixy="-8.6034E-21"
                    ixz="2.935E-23"
                    iyy="2.7774E-06"
                    iyz="1.1729E-11"
                    izz="4.07E-06" />
            </inertial>
            <visual>
                <origin
                    xyz="0 0 0"
                    rpy="0 0 0" />
                <geometry>
                    <mesh
                        filename="package://snake_simulate/meshes/snake_with_wheel_Wheel_1.STL" />
                </geometry>
                <material
                    name="">
                    <color
                        rgba="0.79608 0.82353 0.93725 1" />
                </material>
            </visual>
            <collision>
                <origin
                    xyz="0 0 0"
                    rpy="0 0 0" />
                <geometry>
                    <mesh
                    filename="package://snake_simulate/meshes/snake_with_wheel_Wheel_1.STL" />
                </geometry>
            </collision>
        </link>
        <joint
            name="Wheel_joint_${ID3}"
            type="continuous">
            <origin
                xyz="-0.0269 -0.030156 0"
                rpy="-1.5708 0 0" />
            <parent
                link="Link_${ID2}" />
            <child
                link="Wheel_${ID3}" />
            <axis
                xyz="0 1 0" />
            <limit
                lower="0"
                upper="0"
                effort="0"
                velocity="100" />
        </joint>
        <gazebo reference="base_link">
            <material>Gazebo/Blue</material>
            <implicitSpringDamper>1</implicitSpringDamper>
            <kp>1000000.0</kp>
            <kd>1.0</kd>
            <mu1>0.5</mu1>
            <mu2>0.5</mu2>
            <minDepth>0.001</minDepth>
        </gazebo>
        <gazebo reference="Link_${ID1}">
            <material>Gazebo/Orange</material>
            <implicitSpringDamper>1</implicitSpringDamper>
            <kp>1000000.0</kp>
            <kd>1.0</kd>
            <mu1>0.5</mu1>
            <mu2>0.5</mu2>
            <minDepth>0.001</minDepth>
        </gazebo>
        <transmission name="Tran_${ID1}">
            <type>transmission_interface/SimpleTransmission</type>
            <joint name="Joint_${ID1}">
                <hardwareInterface>hardware_interface/EffortJointInterface</hardwareInterface>
            </joint>
            <actuator name="Motor_${ID1}">
                <mechanicalReduction>1</mechanicalReduction>
                <hardwareInterface>hardware_interface/EffortJointInterface</hardwareInterface>
            </actuator>
        </transmission>
        <gazebo reference="Link_${ID2}">
            <material>Gazebo/Blue</material>
            <implicitSpringDamper>1</implicitSpringDamper>
            <kp>1000000.0</kp>
            <kd>1.0</kd>
            <mu1>0.5</mu1>
            <mu2>0.5</mu2>
            <minDepth>0.001</minDepth>
        </gazebo>
        <transmission name="Tran_${ID2}">
            <type>transmission_interface/SimpleTransmission</type>
            <joint name="Joint_${ID2}">
                <hardwareInterface>hardware_interface/EffortJointInterface</hardwareInterface>
            </joint>
            <actuator name="Motor_${ID2}">
                <mechanicalReduction>1</mechanicalReduction>
                <hardwareInterface>hardware_interface/EffortJointInterface</hardwareInterface>
            </actuator>
        </transmission>
        <gazebo reference="Wheel_1">
            <material>Gazebo/Blue</material>
            <implicitSpringDamper>1</implicitSpringDamper>
            <kp>1000000.0</kp>
            <kd>1.0</kd>
            <mu1>0.5</mu1>
            <mu2>0.5</mu2>
            <minDepth>0.001</minDepth>
        </gazebo>
        <transmission name="Wheel_Tran_1">
            <type>transmission_interface/SimpleTransmission</type>
            <joint name="Wheel_joint_1">
                <hardwareInterface>hardware_interface/EffortJointInterface</hardwareInterface>
            </joint>
            <actuator name="Wheel_Motor_1">
                <mechanicalReduction>1</mechanicalReduction>
                <hardwareInterface>hardware_interface/EffortJointInterface</hardwareInterface>
            </actuator>
        </transmission>
        <gazebo reference="Wheel_${ID3}">
            <material>Gazebo/Blue</material>
            <implicitSpringDamper>1</implicitSpringDamper>
            <kp>1000000.0</kp>
            <kd>1.0</kd>
            <mu1>0.5</mu1>
            <mu2>0.5</mu2>
            <minDepth>0.001</minDepth>
        </gazebo>
        <transmission name="Wheel_Tran_${ID3}">
            <type>transmission_interface/SimpleTransmission</type>
            <joint name="Wheel_joint_${ID3}">
                <hardwareInterface>hardware_interface/EffortJointInterface</hardwareInterface>
            </joint>
            <actuator name="Wheel_Motor_${ID3}">
                <mechanicalReduction>1</mechanicalReduction>
                <hardwareInterface>hardware_interface/EffortJointInterface</hardwareInterface>
            </actuator>
        </transmission>
    </xacro:macro>
</robot>